Workbook
Name DiaSinTrabajo: 46281
Name Print_Titles: Gantt!$5:$8

Sheet Gantt
A1: Diagrama de Gantt · Proyecto de Computación Gráfica (Visualizador de Rectas)
A2: Metodología Scrum · 5 sprints semanales - Aplicación de escritorio en Python (CustomTkinter + Matplotlib)
A3: Inicio: | B3: =Equipo!B12 -> 46251 | C3: Fin: | D3: =Equipo!B13 -> 46286
B4: =Equipo!B5 -> Gunther Nettel Rosario | E4: Fin de semana
B5: =Equipo!B6 -> Alberto Rasgado | H5: Agosto 2026 | W5: Septiembre 2026
B6: =Equipo!B7 -> Ulises Chauk Arias Santiz | H6: Sem 1 · Sprint 0 | O6: Sem 2 · Sprint 1 | V6: Sem 3 · Sprint 2 | AC6: Sem 4 · Sprint 3 | AJ6: Sem 5 · Sprint 4 | AQ6: Ent.
B7: =Equipo!B8 -> Todo el equipo | H7: =MID("LMXJVSD",WEEKDAY(H8,2),1) -> L | I7: =MID("LMXJVSD",WEEKDAY(I8,2),1) -> M | J7: =MID("LMXJVSD",WEEKDAY(J8,2),1) -> X | K7: =MID("LMXJVSD",WEEKDAY(K8,2),1) -> J | L7: =MID("LMXJVSD",WEEKDAY(L8,2),1) -> V | M7: =MID("LMXJVSD",WEEKDAY(M8,2),1) -> S | N7: =MID("LMXJVSD",WEEKDAY(N8,2),1) -> D | O7: =MID("LMXJVSD",WEEKDAY(O8,2),1) -> L | ... AQ7: =MID("LMXJVSD",WEEKDAY(AQ8,2),1) -> L
A8: Sprint | B8: Tarea | C8: Responsable | D8: Inicio | E8: Fin | F8: Estado | H8: =Equipo!$B$12 -> 46251 | I8: =H8+1 -> 46252 | J8: =I8+1 -> 46253 | K8: =J8+1 -> 46254 | L8: =K8+1 -> 46255 | M8: =L8+1 -> 46256 | N8: =M8+1 -> 46257 | O8: =N8+1 -> 46258 | P8: =O8+1 -> 46259 | ... AQ8: =AP8+1 -> 46286
A9: Sprint 0 | B9: Kick-off, requerimientos y Product Backlog | C9: =Equipo!$B$8 -> Todo el equipo | D9: 46251 | E9: 46251 | F9: Completado
A10: Sprint 0 | B10: Investigación: pendiente, ecuación y trazo de rectas | C10: =Equipo!$B$6 -> Alberto Rasgado | D10: 46252 | E10: 46254 | F10: Completado
A11: Sprint 0 | B11: Selección de stack (CustomTkinter, Matplotlib, CTkTable) y entorno virtual | C11: =Equipo!$B$5 -> Gunther Nettel Rosario | D11: 46252 | E11: 46253 | F11: Completado
A12: Sprint 0 | B12: Configuración del repositorio Git y estructura de carpetas | C12: =Equipo!$B$5 -> Gunther Nettel Rosario | D12: 46254 | E12: 46255 | F12: Completado
A13: Sprint 0 | B13: Wireframes de la interfaz (sidebar, plano, tabla, tarjetas) | C13: =Equipo!$B$7 -> Ulises Chauk Arias Santiz | D13: 46252 | E13: 46255 | F13: Completado
A14: Sprint 0 | B14: Sprint Review y Retrospectiva | C14: =Equipo!$B$8 -> Todo el equipo | D14: 46255 | E14: 46255 | F14: Completado
A15: Sprint 1 | B15: Sprint Planning | C15: =Equipo!$B$8 -> Todo el equipo | D15: 46258 | E15: 46258 | F15: Completado
A16: Sprint 1 | B16: Ventana principal: layout en grid y tema visual | C16: =Equipo!$B$5 -> Gunther Nettel Rosario | D16: 46258 | E16: 46260 | F16: Completado
A17: Sprint 1 | B17: Barra lateral con botones de navegación | C17: =Equipo!$B$5 -> Gunther Nettel Rosario | D17: 46261 | E17: 46262 | F17: Completado
A18: Sprint 1 | B18: Gestor de páginas y listeners de navegación | C18: =Equipo!$B$6 -> Alberto Rasgado | D18: 46259 | E18: 46262 | F18: Completado
A19: Sprint 1 | B19: Sistema de iconos vectoriales (PIL + CTkImage, supersampling) | C19: =Equipo!$B$7 -> Ulises Chauk Arias Santiz | D19: 46259 | E19: 46261 | F19: Completado
A20: Sprint 1 | B20: Página "Módulo Futuro" | C20: =Equipo!$B$7 -> Ulises Chauk Arias Santiz | D20: 46262 | E20: 46262 | F20: Completado
A21: Sprint 2 | B21: Sprint Planning | C21: =Equipo!$B$8 -> Todo el equipo | D21: 46265 | E21: 46265 | F21: Completado
A22: Sprint 2 | B22: Funciones de pendiente, ordenada, ecuación y dirección | C22: =Equipo!$B$6 -> Alberto Rasgado | D22: 46266 | E22: 46267 | F22: Completado
A23: Sprint 2 | B23: Generación de puntos de la trayectoria | C23: =Equipo!$B$6 -> Alberto Rasgado | D23: 46268 | E23: 46269 | F23: Completado
A24: Sprint 2 | B24: Plano cartesiano Matplotlib (ejes, escala 1:1, render) | C24: =Equipo!$B$5 -> Gunther Nettel Rosario | D24: 46266 | E24: 46268 | F24: Completado
A25: Sprint 2 | B25: Formulario de entrada (x1, y1, x2, y2) y botones Calcular / Limpiar | C25: =Equipo!$B$7 -> Ulises Chauk Arias Santiz | D25: 46266 | E25: 46267 | F25: Completado
A26: Sprint 2 | B26: Tarjetas de datos analíticos (pendiente, ecuación, incrementos) | C26: =Equipo!$B$7 -> Ulises Chauk Arias Santiz | D26: 46268 | E26: 46269 | F26: Completado
A27: Sprint 2 | B27: Integración cálculo ↔ gráfica | C27: =Equipo!$B$5 -> Gunther Nettel Rosario | D27: 46269 | E27: 46269 | F27: Completado
A28: Sprint 3 | B28: Sprint Planning | C28: =Equipo!$B$8 -> Todo el equipo | D28: 46272 | E28: 46272 | F28: Completado
A29: Sprint 3 | B29: Tabla CTkTable con los puntos y pasos de la recta | C29: =Equipo!$B$6 -> Alberto Rasgado | D29: 46272 | E29: 46273 | F29: Completado
A30: Sprint 3 | B30: Clasificación: 4 positivos, 4 negativos y 3 especiales (clasificar_recta) | C30: =Equipo!$B$6 -> Alberto Rasgado | D30: 46274 | E30: 46276 | F30: Completado
A31: Sprint 3 | B31: Recta vertical y punto único: cálculo y dibujo | C31: =Equipo!$B$5 -> Gunther Nettel Rosario | D31: 46273 | E31: 46274 | F31: Completado
A32: Sprint 3 | B32: Pruebas unitarias de la lógica y de todos los casos de trazo | C32: =Equipo!$B$5 -> Gunther Nettel Rosario | D32: 46275 | E32: 46276 | F32: Completado
A33: Sprint 3 | B33: Validación de entradas y manejo de errores | C33: =Equipo!$B$7 -> Ulises Chauk Arias Santiz | D33: 46273 | E33: 46274 | F33: Completado
A34: Sprint 3 | B34: Franja «Caso detectado» en la interfaz | C34: =Equipo!$B$7 -> Ulises Chauk Arias Santiz | D34: 46275 | E34: 46276 | F34: Completado
A35: Sprint 4 | B35: Sprint Planning | C35: =Equipo!$B$8 -> Todo el equipo | D35: 46279 | E35: 46279 | F35: Completado
A36: Sprint 4 | B36: Rediseño visual: esquinas redondeadas, paleta y tipografía | C36: =Equipo!$B$6 -> Alberto Rasgado | D36: 46279 | E36: 46282 | F36: Completado
A37: Sprint 4 | B37: Ecuaciones simplificadas (y = x, y = 2, x = 3) | C37: =Equipo!$B$6 -> Alberto Rasgado | D37: 46283 | E37: 46283 | F37: Completado
A38: Sprint 4 | B38: Modo Oscuro / Claro con CTkSwitch y sincronización del plano | C38: =Equipo!$B$7 -> Ulises Chauk Arias Santiz | D38: 46279 | E38: 46280 | F38: Completado
A39: Sprint 4 | B39: Plano predominante (>80 %) y ajuste responsivo | C39: =Equipo!$B$5 -> Gunther Nettel Rosario | D39: 46279 | E39: 46280 | F39: Completado
A40: Sprint 4 | B40: Pruebas de navegación, interacción y regresión | C40: =Equipo!$B$5 -> Gunther Nettel Rosario | D40: 46282 | E40: 46283 | F40: Completado
...

Sheet Equipo
A1: Equipo del proyecto y parámetros
A4: Clave | B4: Integrante | C4: Rol en Scrum | D4: Responsabilidades principales
A5: P1 | B5: Gunther Nettel Rosario | C5: Scrum Master - Desarrollador | D5: Arquitectura (main.py), plano cartesiano Matplotlib, recta vertical y punto único, repositorio, pruebas automatizadas
A6: P2 | B6: Alberto Rasgado | C6: Desarrollador | D6: Lógica matemática de la recta, trayectoria, tabla CTkTable, clasificación de casos (4 positivos, 4 negativos, 3 especiales), rediseño visual
A7: P3 | B7: Ulises Chauk Arias Santiz | C7: Desarrollador | D7: Navegación, iconos vectoriales, formulario, tarjetas analíticas, franja de caso detectado, temas, documentación
A8: EQ | B8: Todo el equipo | C8: — | D8: Ceremonias Scrum (planning, review, retro) y entrega
A11: Parámetros del proyecto
A12: Fecha de inicio | B12: 46251
A13: Fecha de fin | B13: 46286
A14: Metodología | B14: Scrum - sprints de 1 semana (lun–vie)

Sheet Carga de trabajo
A1: Distribución de la carga de trabajo
A4: Integrante | B4: Rol | C4: Tareas asignadas | D4: Días en tareas | E4: % de la carga | F4: Reuniones de equipo
A5: =Equipo!B5 -> Gunther Nettel Rosario | B5: =Equipo!C5 -> Scrum Master - Desarrollador | C5: =COUNTIF(Gantt!$C$9:$C$43,A5) -> 10 | D5: =SUMPRODUCT((Gantt!$C$9:$C$43=A5)*(Gantt!$E$9:$E$43-Gantt!$D$9:$D$43+1))-COUNTIFS(Gantt!$C$9:$C$43,A5,Gantt!$D$9:$D$43,"<="&DiaSinTrabajo,Gantt!$E$9:$E$43,">="&DiaSinTrabajo) -> 21 | E5: =IF(SUM($D$5:$D$7)=0,0,D5/SUM($D$5:$D$7)) -> 0.3442623 | F5: =COUNTIF(Gantt!$C$9:$C$43,Equipo!$B$8) -> 8
A6: =Equipo!B6 -> Alberto Rasgado | B6: =Equipo!C6 -> Desarrollador | C6: =COUNTIF(Gantt!$C$9:$C$43,A6) -> 8 | D6: =SUMPRODUCT((Gantt!$C$9:$C$43=A6)*(Gantt!$E$9:$E$43-Gantt!$D$9:$D$43+1))-COUNTIFS(Gantt!$C$9:$C$43,A6,Gantt!$D$9:$D$43,"<="&DiaSinTrabajo,Gantt!$E$9:$E$43,">="&DiaSinTrabajo) -> 20 | E6: =IF(SUM($D$5:$D$7)=0,0,D6/SUM($D$5:$D$7)) -> 0.32786885 | F6: =COUNTIF(Gantt!$C$9:$C$43,Equipo!$B$8) -> 8
A7: =Equipo!B7 -> Ulises Chauk Arias Santiz | B7: =Equipo!C7 -> Desarrollador | C7: =COUNTIF(Gantt!$C$9:$C$43,A7) -> 9 | D7: =SUMPRODUCT((Gantt!$C$9:$C$43=A7)*(Gantt!$E$9:$E$43-Gantt!$D$9:$D$43+1))-COUNTIFS(Gantt!$C$9:$C$43,A7,Gantt!$D$9:$D$43,"<="&DiaSinTrabajo,Gantt!$E$9:$E$43,">="&DiaSinTrabajo) -> 20 | E7: =IF(SUM($D$5:$D$7)=0,0,D7/SUM($D$5:$D$7)) -> 0.32786885 | F7: =COUNTIF(Gantt!$C$9:$C$43,Equipo!$B$8) -> 8
A8: Total | C8: =SUM(C5:C7) -> 27 | D8: =SUM(D5:D7) -> 61 | E8: =SUM(E5:E7) -> 1 | F8: =F5 -> 8
A11: Días en tareas por sprint
A12: Sprint | B12: =Equipo!B5 -> Gunther Nettel Rosario | C12: =Equipo!B6 -> Alberto Rasgado | D12: =Equipo!B7 -> Ulises Chauk Arias Santiz | E12: Total sprint
A13: Sprint 0 | B13: =SUMPRODUCT((Gantt!$A$9:$A$43=$A13)*(Gantt!$C$9:$C$43=B$12)*(Gantt!$E$9:$E$43-Gantt!$D$9:$D$43+1))-COUNTIFS(Gantt!$A$9:$A$43,$A13,Gantt!$C$9:$C$43,B$12,Gantt!$D$9:$D$43,"<="&DiaSinTrabajo,Gantt!$E$9:$E$43,">="&DiaSinTrabajo) -> 4 | C13: =SUMPRODUCT((Gantt!$A$9:$A$43=$A13)*(Gantt!$C$9:$C$43=C$12)*(Gantt!$E$9:$E$43-Gantt!$D$9:$D$43+1))-COUNTIFS(Gantt!$A$9:$A$43,$A13,Gantt!$C$9:$C$43,C$12,Gantt!$D$9:$D$43,"<="&DiaSinTrabajo,Gantt!$E$9:$E$43,">="&DiaSinTrabajo) -> 3 | D13: =SUMPRODUCT((Gantt!$A$9:$A$43=$A13)*(Gantt!$C$9:$C$43=D$12)*(Gantt!$E$9:$E$43-Gantt!$D$9:$D$43+1))-COUNTIFS(Gantt!$A$9:$A$43,$A13,Gantt!$C$9:$C$43,D$12,Gantt!$D$9:$D$43,"<="&DiaSinTrabajo,Gantt!$E$9:$E$43,">="&DiaSinTrabajo) -> 4 | E13: =SUM(B13:D13) -> 11
A14: Sprint 1 | B14: =SUMPRODUCT((Gantt!$A$9:$A$43=$A14)*(Gantt!$C$9:$C$43=B$12)*(Gantt!$E$9:$E$43-Gantt!$D$9:$D$43+1))-COUNTIFS(Gantt!$A$9:$A$43,$A14,Gantt!$C$9:$C$43,B$12,Gantt!$D$9:$D$43,"<="&DiaSinTrabajo,Gantt!$E$9:$E$43,">="&DiaSinTrabajo) -> 5 | C14: =SUMPRODUCT((Gantt!$A$9:$A$43=$A14)*(Gantt!$C$9:$C$43=C$12)*(Gantt!$E$9:$E$43-Gantt!$D$9:$D$43+1))-COUNTIFS(Gantt!$A$9:$A$43,$A14,Gantt!$C$9:$C$43,C$12,Gantt!$D$9:$D$43,"<="&DiaSinTrabajo,Gantt!$E$9:$E$43,">="&DiaSinTrabajo) -> 4 | D14: =SUMPRODUCT((Gantt!$A$9:$A$43=$A14)*(Gantt!$C$9:$C$43=D$12)*(Gantt!$E$9:$E$43-Gantt!$D$9:$D$43+1))-COUNTIFS(Gantt!$A$9:$A$43,$A14,Gantt!$C$9:$C$43,D$12,Gantt!$D$9:$D$43,"<="&DiaSinTrabajo,Gantt!$E$9:$E$43,">="&DiaSinTrabajo) -> 4 | E14: =SUM(B14:D14) -> 13
A15: Sprint 2 | B15: =SUMPRODUCT((Gantt!$A$9:$A$43=$A15)*(Gantt!$C$9:$C$43=B$12)*(Gantt!$E$9:$E$43-Gantt!$D$9:$D$43+1))-COUNTIFS(Gantt!$A$9:$A$43,$A15,Gantt!$C$9:$C$43,B$12,Gantt!$D$9:$D$43,"<="&DiaSinTrabajo,Gantt!$E$9:$E$43,">="&DiaSinTrabajo) -> 4 | C15: =SUMPRODUCT((Gantt!$A$9:$A$43=$A15)*(Gantt!$C$9:$C$43=C$12)*(Gantt!$E$9:$E$43-Gantt!$D$9:$D$43+1))-COUNTIFS(Gantt!$A$9:$A$43,$A15,Gantt!$C$9:$C$43,C$12,Gantt!$D$9:$D$43,"<="&DiaSinTrabajo,Gantt!$E$9:$E$43,">="&DiaSinTrabajo) -> 4 | D15: =SUMPRODUCT((Gantt!$A$9:$A$43=$A15)*(Gantt!$C$9:$C$43=D$12)*(Gantt!$E$9:$E$43-Gantt!$D$9:$D$43+1))-COUNTIFS(Gantt!$A$9:$A$43,$A15,Gantt!$C$9:$C$43,D$12,Gantt!$D$9:$D$43,"<="&DiaSinTrabajo,Gantt!$E$9:$E$43,">="&DiaSinTrabajo) -> 4 | E15: =SUM(B15:D15) -> 12
A16: Sprint 3 | B16: =SUMPRODUCT((Gantt!$A$9:$A$43=$A16)*(Gantt!$C$9:$C$43=B$12)*(Gantt!$E$9:$E$43-Gantt!$D$9:$D$43+1))-COUNTIFS(Gantt!$A$9:$A$43,$A16,Gantt!$C$9:$C$43,B$12,Gantt!$D$9:$D$43,"<="&DiaSinTrabajo,Gantt!$E$9:$E$43,">="&DiaSinTrabajo) -> 4 | C16: =SUMPRODUCT((Gantt!$A$9:$A$43=$A16)*(Gantt!$C$9:$C$43=C$12)*(Gantt!$E$9:$E$43-Gantt!$D$9:$D$43+1))-COUNTIFS(Gantt!$A$9:$A$43,$A16,Gantt!$C$9:$C$43,C$12,Gantt!$D$9:$D$43,"<="&DiaSinTrabajo,Gantt!$E$9:$E$43,">="&DiaSinTrabajo) -> 5 | D16: =SUMPRODUCT((Gantt!$A$9:$A$43=$A16)*(Gantt!$C$9:$C$43=D$12)*(Gantt!$E$9:$E$43-Gantt!$D$9:$D$43+1))-COUNTIFS(Gantt!$A$9:$A$43,$A16,Gantt!$C$9:$C$43,D$12,Gantt!$D$9:$D$43,"<="&DiaSinTrabajo,Gantt!$E$9:$E$43,">="&DiaSinTrabajo) -> 4 | E16: =SUM(B16:D16) -> 13
A17: Sprint 4 | B17: =SUMPRODUCT((Gantt!$A$9:$A$43=$A17)*(Gantt!$C$9:$C$43=B$12)*(Gantt!$E$9:$E$43-Gantt!$D$9:$D$43+1))-COUNTIFS(Gantt!$A$9:$A$43,$A17,Gantt!$C$9:$C$43,B$12,Gantt!$D$9:$D$43,"<="&DiaSinTrabajo,Gantt!$E$9:$E$43,">="&DiaSinTrabajo) -> 4 | C17: =SUMPRODUCT((Gantt!$A$9:$A$43=$A17)*(Gantt!$C$9:$C$43=C$12)*(Gantt!$E$9:$E$43-Gantt!$D$9:$D$43+1))-COUNTIFS(Gantt!$A$9:$A$43,$A17,Gantt!$C$9:$C$43,C$12,Gantt!$D$9:$D$43,"<="&DiaSinTrabajo,Gantt!$E$9:$E$43,">="&DiaSinTrabajo) -> 4 | D17: =SUMPRODUCT((Gantt!$A$9:$A$43=$A17)*(Gantt!$C$9:$C$43=D$12)*(Gantt!$E$9:$E$43-Gantt!$D$9:$D$43+1))-COUNTIFS(Gantt!$A$9:$A$43,$A17,Gantt!$C$9:$C$43,D$12,Gantt!$D$9:$D$43,"<="&DiaSinTrabajo,Gantt!$E$9:$E$43,">="&DiaSinTrabajo) -> 4 | E17: =SUM(B17:D17) -> 12
A18: Total | B18: =SUM(B13:B17) -> 21 | C18: =SUM(C13:C17) -> 20 | D18: =SUM(D13:D17) -> 20 | E18: =SUM(E13:E17) -> 61
